<?xml version="1.0" encoding="utf-8"?>
<!-- This URDF was automatically created by SolidWorks to URDF Exporter! Originally created by Stephen Brawner (brawner@gmail.com) 
     Commit Version: 1.6.0-4-g7f85cfe  Build Version: 1.6.7995.38578
     For more information, please see http://wiki.ros.org/sw_urdf_exporter -->
<robot
  name="ur3">
  <link
    name="base_link">
    <inertial>
      <origin
        xyz="3.8786E-05 0.04622 0.00080892"
        rpy="0 0 0" />
      <mass
        value="0.61577" />
      <inertia
        ixx="0.00076128"
        ixy="3.5087E-07"
        ixz="-3.0273E-07"
        iyy="0.0010029"
        iyz="3.469E-06"
        izz="0.00077456" />
    </inertial>
    <visual>
      <origin
        xyz="0 0 0"
        rpy="0 0 0" />
      <geometry>
        <mesh
          filename="package://ur3/meshes/base_link.STL" />
      </geometry>
      <material
        name="">
        <color
          rgba="0.89804 0.91765 0.92941 1" />
      </material>
    </visual>
    <collision>
      <origin
        xyz="0 0 0"
        rpy="0 0 0" />
      <geometry>
        <mesh
          filename="package://ur3/meshes/base_link.STL" />
      </geometry>
    </collision>
  </link>
  <link
    name="link1">
    <inertial>
      <origin
        xyz="-6.6109E-06 0.055939 0.0073371"
        rpy="0 0 0" />
      <mass
        value="0.756" />
      <inertia
        ixx="0.001069"
        ixy="-9.4386E-08"
        ixz="1.0327E-07"
        iyy="0.00090659"
        iyz="-0.00013106"
        izz="0.00099021" />
    </inertial>
    <visual>
      <origin
        xyz="0 0 0"
        rpy="0 0 0" />
      <geometry>
        <mesh
          filename="package://ur3/meshes/link1.STL" />
      </geometry>
      <material
        name="">
        <color
          rgba="0.79216 0.81961 0.93333 1" />
      </material>
    </visual>
    <collision>
      <origin
        xyz="0 0 0"
        rpy="0 0 0" />
      <geometry>
        <mesh
          filename="package://ur3/meshes/link1.STL" />
      </geometry>
    </collision>
  </link>
  <joint
    name="joint1"
    type="revolute">
    <origin
      xyz="0 0 0.0844"
      rpy="1.5708 0 -3.1416" />
    <parent
      link="base_link" />
    <child
      link="link1" />
    <axis
      xyz="0 1 0" />
    <limit
      lower="-3.14"
      upper="3.14"
      effort="100"
      velocity="1" />
  </joint>
  <link
    name="link2">
    <inertial>
      <origin
        xyz="-2.4275E-06 0.064246 0.10569"
        rpy="0 0 0" />
      <mass
        value="1.802" />
      <inertia
        ixx="0.0026498"
        ixy="-9.0231E-08"
        ixz="1.0346E-07"
        iyy="0.0025175"
        iyz="-8.1097E-05"
        izz="0.0016701" />
    </inertial>
    <visual>
      <origin
        xyz="0 0 0"
        rpy="0 0 0" />
      <geometry>
        <mesh
          filename="package://ur3/meshes/link2.STL" />
      </geometry>
      <material
        name="">
        <color
          rgba="0.79216 0.81961 0.93333 1" />
      </material>
    </visual>
    <collision>
      <origin
        xyz="0 0 0"
        rpy="0 0 0" />
      <geometry>
        <mesh
          filename="package://ur3/meshes/link2.STL" />
      </geometry>
    </collision>
  </link>
  <joint
    name="joint2"
    type="revolute">
    <origin
      xyz="0 0.0675 0.05235"
      rpy="1.5708 0 -3.1416" />
    <parent
      link="link1" />
    <child
      link="link2" />
    <axis
      xyz="0 -1 0" />
    <limit
      lower="-3.14"
      upper="3.14"
      effort="100"
      velocity="1" />
  </joint>
  <link
    name="link3">
    <inertial>
      <origin
        xyz="-0.0051485 -0.11117 -5.3349E-07"
        rpy="0 0 0" />
      <mass
        value="0.9624" />
      <inertia
        ixx="0.001015"
        ixy="4.6188E-05"
        ixz="1.0584E-08"
        iyy="0.00054278"
        iyz="-9.3595E-09"
        izz="0.0010729" />
    </inertial>
    <visual>
      <origin
        xyz="0 0 0"
        rpy="0 0 0" />
      <geometry>
        <mesh
          filename="package://ur3/meshes/link3.STL" />
      </geometry>
      <material
        name="">
        <color
          rgba="1 1 1 1" />
      </material>
    </visual>
    <collision>
      <origin
        xyz="0 0 0"
        rpy="0 0 0" />
      <geometry>
        <mesh
          filename="package://ur3/meshes/link3.STL" />
      </geometry>
    </collision>
  </link>
  <joint
    name="joint3"
    type="revolute">
    <origin
      xyz="0 -0.02535 0.24365"
      rpy="-1.5708 0 -1.5708" />
    <parent
      link="link2" />
    <child
      link="link3" />
    <axis
      xyz="1 0 0" />
    <limit
      lower="-3.14"
      upper="3.14"
      effort="100"
      velocity="1" />
  </joint>
  <link
    name="link4">
    <inertial>
      <origin
        xyz="0.0059208 -0.00051754 1.4538E-07"
        rpy="0 0 0" />
      <mass
        value="0.3252" />
      <inertia
        ixx="0.00019459"
        ixy="1.8339E-05"
        ixz="6.3684E-10"
        iyy="0.00019909"
        iyz="5.1705E-10"
        izz="0.00022621" />
    </inertial>
    <visual>
      <origin
        xyz="0 0 0"
        rpy="0 0 0" />
      <geometry>
        <mesh
          filename="package://ur3/meshes/link4.STL" />
      </geometry>
      <material
        name="">
        <color
          rgba="1 1 1 1" />
      </material>
    </visual>
    <collision>
      <origin
        xyz="0 0 0"
        rpy="0 0 0" />
      <geometry>
        <mesh
          filename="package://ur3/meshes/link4.STL" />
      </geometry>
    </collision>
  </link>
  <joint
    name="joint4"
    type="revolute">
    <origin
      xyz="-0.0834 -0.213 0"
      rpy="-3.1416 0 0" />
    <parent
      link="link3" />
    <child
      link="link4" />
    <axis
      xyz="1 0 0" />
    <limit
      lower="-3.14"
      upper="3.14"
      effort="100"
      velocity="1" />
  </joint>
  <link
    name="link5">
    <inertial>
      <origin
        xyz="0.0059208 0.00051754 -1.6526E-07"
        rpy="0 0 0" />
      <mass
        value="0.3252" />
      <inertia
        ixx="0.00019459"
        ixy="-1.834E-05"
        ixz="-6.5236E-10"
        iyy="0.00019909"
        iyz="5.3475E-10"
        izz="0.00022621" />
    </inertial>
    <visual>
      <origin
        xyz="0 0 0"
        rpy="0 0 0" />
      <geometry>
        <mesh
          filename="package://ur3/meshes/link5.STL" />
      </geometry>
      <material
        name="">
        <color
          rgba="1 1 1 1" />
      </material>
    </visual>
    <collision>
      <origin
        xyz="0 0 0"
        rpy="0 0 0" />
      <geometry>
        <mesh
          filename="package://ur3/meshes/link5.STL" />
      </geometry>
    </collision>
  </link>
  <joint
    name="joint5"
    type="revolute">
    <origin
      xyz="0 0.0834 0"
      rpy="0 0 -1.5708" />
    <parent
      link="link4" />
    <child
      link="link5" />
    <axis
      xyz="-1 0 0" />
    <limit
      lower="-3.14"
      upper="3.14"
      effort="100"
      velocity="0" />
  </joint>
  <link
    name="link6">
    <inertial>
      <origin
        xyz="-1.0101E-10 0.0001033 -0.021073"
        rpy="0 0 0" />
      <mass
        value="0.11536" />
      <inertia
        ixx="4.2472E-05"
        ixy="-5.8594E-13"
        ixz="1.0897E-12"
        iyy="4.2687E-05"
        iyz="1.0322E-07"
        izz="5.9069E-05" />
    </inertial>
    <visual>
      <origin
        xyz="0 0 0"
        rpy="0 0 0" />
      <geometry>
        <mesh
          filename="package://ur3/meshes/link6.STL" />
      </geometry>
      <material
        name="">
        <color
          rgba="1 1 1 1" />
      </material>
    </visual>
    <collision>
      <origin
        xyz="0 0 0"
        rpy="0 0 0" />
      <geometry>
        <mesh
          filename="package://ur3/meshes/link6.STL" />
      </geometry>
    </collision>
  </link>
  <joint
    name="joint6"
    type="revolute">
    <origin
      xyz="0 -0.0409 0"
      rpy="1.5708 -1.5708 0" />
    <parent
      link="link5" />
    <child
      link="link6" />
    <axis
      xyz="0 0 1" />
    <limit
      lower="-3.14"
      upper="3.14"
      effort="100"
      velocity="1" />
  </joint>
</robot>